Workbook

Sheet Lecture Plan
A1: HINDU GIRLS COLLEGE, SONIPAT
A2: Affiliated to MD University, Rohtak, Haryana
A3: Department of Computer Applications
A4: COURSE WORK PLAN – LECTURE-WISE SCHEDULE
A5: Python Programming | MCA Sem II | A.Y. 2026-27 | OBE (Bloom's aligned)
A7: Programme | D7: MCA (Master of Computer Applications) | F7: Semester | G7: II
A8: Course | D8: Python Programming | F8: Academic Year | G8: 2026-27
A9: Total Lectures | D9: 35 | F9: Lecture Days | G9: Monday, Wednesday, Friday
A10: Course Start Date | D10: 46389 | F10: Course End Date | G10: =MAX($B$14:$B$53) -> 46472
A11: Faculty | D11: Dr Pankaj Kumar Jain, Assistant Professor | F11: Holidays Excluded | G11: 15-Jan-2027 (Sankranti, Fri) falls on a lecture day and is skipped; 14-Jan, 26-Jan, 09-Feb and 02-Mar fall on non-lecture days; 07-Apr falls after the course end date
A13: S.No | B13: Date | C13: Day | D13: Unit Name | E13: Topic | F13: Pedagogy | G13: Activity | H13: Assignment | I13: CO (Bloom's Level)
A14: UNIT 1: PYTHON FUNDAMENTALS AND CONTROL STRUCTURES | Lectures: 7 | Weightage: 20%
A15: 1 | B15: 46391 | C15: =TEXT(B15,"ddd") -> Mon | D15: Python Fundamentals and Control Structures | E15: Introduction to Python: features, applications, advantages, and limitations; installation, execution environments, interactive mode, and script mode | F15: Interactive lecture | G15: Think-pair-share on Python applications; run a first program in both modes | H15: — | I15: CO1 (K2)
A16: 2 | B16: 46393 | C16: =TEXT(B16,"ddd") -> Wed | D16: Python Fundamentals and Control Structures | E16: Python syntax, indentation, comments, keywords, identifiers, and variables | F16: Live coding | G16: Spot-the-error on indentation and identifier snippets | H16: — | I16: CO1 (K2)
A17: 3 | B17: 46395 | C17: =TEXT(B17,"ddd") -> Fri | D17: Python Fundamentals and Control Structures | E17: Data types: numeric, Boolean, string, and None types; type conversion and type checking | F17: Gamified quiz | G17: Predict-the-output quiz on type() and conversions | H17: — | I17: CO1 (K3)
A18: 4 | B18: 46398 | C18: =TEXT(B18,"ddd") -> Mon | D18: Python Fundamentals and Control Structures | E18: Operators: arithmetic, relational, logical, assignment, bitwise, membership, and identity | F18: Peer instruction | G18: Concept-test voting on operator precedence and is vs == | H18: — | I18: CO1 (K3)
A19: 5 | B19: 46400 | C19: =TEXT(B19,"ddd") -> Wed | D19: Python Fundamentals and Control Structures | E19: Input and output operations; formatted output using f-strings; decision-making statements: if, if-else, and nested if | F19: Pair programming | G19: Build a formatted bill program with eligibility checks | H19: — | I19: CO1 (K3)
A20: 6 | B20: 46405 | C20: =TEXT(B20,"ddd") -> Mon | D20: Python Fundamentals and Control Structures | E20: Iterative statements: for, while, range(), break, continue, and pass | F20: Flipped classroom | G20: Pattern-printing and loop-tracing tasks after a pre-class video | H20: — | I20: CO1 (K3)
A21: 7 | B21: 46407 | C21: =TEXT(B21,"ddd") -> Wed | D21: Python Fundamentals and Control Structures | E21: Basic problem-solving using algorithms and Python programs | F21: Group discussion | G21: Algorithm-to-code relay for a given problem | H21: Write algorithms, flowcharts and Python programs for five problems (prime check, Fibonacci, number patterns, menu-driven calculator, digit sum) [CO1 | K3] | I21: CO1 (K3)
A22: UNIT 2: DATA STRUCTURES, FUNCTIONS, AND MODULES | Lectures: 7 | Weightage: 20%
A23: 8 | B23: 46409 | C23: =TEXT(B23,"ddd") -> Fri | D23: Data Structures, Functions, and Modules | E23: Strings: indexing, slicing, string operations, formatting, and commonly used methods | F23: Live coding | G23: Palindrome check and word count using slicing and methods | H23: — | I23: CO2 (K3)
A24: 9 | B24: 46412 | C24: =TEXT(B24,"ddd") -> Mon | D24: Data Structures, Functions, and Modules | E24: Lists: creation, indexing, slicing, traversal, methods, and list comprehensions | F24: Interactive lecture | G24: Rewrite loops as list comprehensions | H24: — | I24: CO2 (K3)
A25: 10 | B25: 46414 | C25: =TEXT(B25,"ddd") -> Wed | D25: Data Structures, Functions, and Modules | E25: Tuples: creation, operations, packing, and unpacking; Sets: creation, operations, and set methods | F25: Think-pair-share | G25: Remove duplicates with sets; match operations to use-cases | H25: — | I25: CO2 (K3)
A26: 11 | B26: 46416 | C26: =TEXT(B26,"ddd") -> Fri | D26: Data Structures, Functions, and Modules | E26: Dictionaries: creation, accessing, updating, deleting, and methods; comparison of built-in data structures and their applications | F26: Case study | G26: Choose the right data structure for a student-record scenario | H26: — | I26: CO2 (K4)
A27: 12 | B27: 46419 | C27: =TEXT(B27,"ddd") -> Mon | D27: Data Structures, Functions, and Modules | E27: Functions: definition, calls, parameters, arguments, return values, and variable scope; argument types: positional, keyword, default, and variable-length arguments | F27: Pair programming | G27: Modularise a calculator using keyword and default arguments | H27: — | I27: CO2 (K3)
A28: 13 | B28: 46421 | C28: =TEXT(B28,"ddd") -> Wed | D28: Data Structures, Functions, and Modules | E28: Recursive functions, lambda functions, and higher-order functions | F28: Jigsaw | G28: Expert groups teach recursion, lambda and map/filter to peers | H28: — | I28: CO2 (K3)
A29: 14 | B29: 46423 | C29: =TEXT(B29,"ddd") -> Fri | D29: Data Structures, Functions, and Modules | E29: Modules and packages: importing, creating user-defined modules, and using standard library modules; commonly used modules: math, random, and datetime | F29: Demonstration | G29: Create a user-defined module; number-guessing game using random | H29: Develop a student/inventory management program using lists, dictionaries, functions and a user-defined module [CO2 | K3] | I29: CO2 (K3)
A30: UNIT 3: OBJECT-ORIENTED PROGRAMMING AND EXCEPTION HANDLING | Lectures: 7 | Weightage: 20%
A31: 15 | B31: 46426 | C31: =TEXT(B31,"ddd") -> Mon | D31: Object-Oriented Programming and Exception Handling | E31: Introduction to object-oriented programming concepts; classes and objects, attributes and methods | F31: Interactive lecture | G31: Model real-world entities (Student, Account) as classes | H31: — | I31: CO3 (K2)
A32: 16 | B32: 46428 | C32: =TEXT(B32,"ddd") -> Wed | D32: Object-Oriented Programming and Exception Handling | E32: Constructors and the __init__() method; instance variables, class variables, instance methods, class methods, and static methods | F32: Live coding | G32: Add parameterised constructors and a class counter to the Student class | H32: — | I32: CO3 (K3)
A33: 17 | B33: 46430 | C33: =TEXT(B33,"ddd") -> Fri | D33: Object-Oriented Programming and Exception Handling | E33: Encapsulation and data hiding | F33: Problem-based learning | G33: Bank account with private balance and getter/setter methods | H33: — | I33: CO3 (K3)
A34: 18 | B34: 46433 | C34: =TEXT(B34,"ddd") -> Mon | D34: Object-Oriented Programming and Exception Handling | E34: Inheritance: single, multiple, multilevel, and hierarchical inheritance; method overriding and polymorphism | F34: Flipped classroom | G34: Build a Person-Student-Teacher hierarchy and predict overridden calls | H34: — | I34: CO3 (K3)
A35: 19 | B35: 46435 | C35: =TEXT(B35,"ddd") -> Wed | D35: Object-Oriented Programming and Exception Handling | E35: Abstraction and abstract classes; special methods and operator overloading | F35: Case study | G35: Shape and Vector classes using abc, __add__ and __str__ | H35: — | I35: CO3 (K4)
A36: 20 | B36: 46437 | C36: =TEXT(B36,"ddd") -> Fri | D36: Object-Oriented Programming and Exception Handling | E36: Exception handling: syntax errors and runtime exceptions; handling using try, except, else, and finally | F36: Gamified quiz | G36: Debug-the-crash challenge: ZeroDivisionError, ValueError | H36: — | I36: CO3 (K3)
A37: 21 | B37: 46440 | C37: =TEXT(B37,"ddd") -> Mon | D37: Object-Oriented Programming and Exception Handling | E37: Raising exceptions using raise and creating user-defined exceptions | F37: Pair programming | G37: Add a custom InsufficientBalanceError to the bank account | H37: Build a library management mini-application using classes, inheritance and custom exception handling [CO3 | K4] | I37: CO3 (K4)
A38: UNIT 4: FILE HANDLING, DATA PROCESSING, AND PYTHON LIBRARIES | Lectures: 8 | Weightage: 22%
A39: 22 | B39: 46442 | C39: =TEXT(B39,"ddd") -> Wed | D39: File Handling, Data Processing, and Python Libraries | E39: File handling: opening, reading, writing, and closing files; file access modes and file object methods | F39: Live coding | G39: Read, write and append a text file; compare r, w and a modes | H39: — | I39: CO4 (K3)
A40: 23 | B40: 46444 | C40: =TEXT(B40,"ddd") -> Fri | D40: File Handling, Data Processing, and Python Libraries | E40: Working with text and binary files; context managers and the with statement | F40: Demonstration | G40: Copy a binary file using the with statement | H40: — | I40: CO4 (K3)
A41: 24 | B41: 46447 | C41: =TEXT(B41,"ddd") -> Mon | D41: File Handling, Data Processing, and Python Libraries | E41: Working with CSV and JSON files using Python modules; introduction to data processing using Python | F41: Pair programming | G41: Convert a student CSV file to JSON and list data-quality issues | H41: — | I41: CO4 (K3)
A42: 25 | B42: 46449 | C42: =TEXT(B42,"ddd") -> Wed | D42: File Handling, Data Processing, and Python Libraries | E42: NumPy: arrays, array creation, indexing, slicing, and basic array operations | F42: Flipped classroom | G42: Array slicing drills and list-vs-array comparison | H42: — | I42: CO4 (K3)
...

Sheet Course Outcomes
A1: HINDU GIRLS COLLEGE, SONIPAT
A2: Affiliated to MD University, Rohtak, Haryana
A3: Department of Computer Applications
A4: COURSE OUTCOMES (COs)
A5: Python Programming | MCA Sem II | A.Y. 2026-27 | OBE (Bloom's aligned)
A7: DRAFT – The syllabus does not list Course Outcomes. These are proposed for faculty confirmation before use in NBA/NAAC documentation.
A9: CO No. | B9: CO Statement (Students will be able to…) | C9: Bloom's Level | D9: Unit(s) | E9: No. of Lectures
A10: CO1 | B10: Apply Python syntax, data types, operators, and control structures to solve basic computational problems. | C10: K3 | D10: Unit I | E10: =COUNTIF('Lecture Plan'!$I$14:$I$53,"CO1*") -> 7
A11: CO2 | B11: Develop modular Python programs using built-in data structures, functions, and standard modules. | C11: K3 | D11: Unit II | E11: =COUNTIF('Lecture Plan'!$I$14:$I$53,"CO2*") -> 7
A12: CO3 | B12: Analyse problem requirements to implement robust object-oriented programs using classes, inheritance, polymorphism, and exception handling. | C12: K4 | D12: Unit III | E12: =COUNTIF('Lecture Plan'!$I$14:$I$53,"CO3*") -> 7
A13: CO4 | B13: Analyse and process file-based and tabular data using NumPy, Pandas, Matplotlib, and regular expressions. | C13: K4 | D13: Unit IV | E13: =COUNTIF('Lecture Plan'!$I$14:$I$53,"CO4*") -> 8
A14: CO5 | B14: Design and develop a Python application integrating database connectivity, web APIs, and unit testing. | C14: K6 | D14: Unit V | E14: =COUNTIF('Lecture Plan'!$I$14:$I$53,"CO5*") -> 6
A15: TOTAL | E15: =SUM(E10:E14) -> 35
A17: BLOOM'S REVISED TAXONOMY – REFERENCE
A18: Level | B18: Action verbs | C18: Category
A19: K1 | B19: Define, list, recall, state, identify | C19: Remember
A20: K2 | B20: Explain, describe, summarise, classify, illustrate | C20: Understand
A21: K3 | B21: Apply, implement, execute, solve, use | C21: Apply
A22: K4 | B22: Analyse, differentiate, compare, examine, debug | C22: Analyse
A23: K5 | B23: Evaluate, justify, assess, critique, validate | C23: Evaluate
A24: K6 | B24: Design, develop, construct, formulate, create | C24: Create

Sheet Session Calendar
A1: HINDU GIRLS COLLEGE, SONIPAT
A2: Affiliated to MD University, Rohtak, Haryana
A3: Department of Computer Applications
A4: SESSION CALENDAR
A5: Python Programming | MCA Sem II | A.Y. 2026-27 | OBE (Bloom's aligned)
A7: JANUARY 2027 | I7: FEBRUARY 2027
A8: Mon | B8: Tue | C8: Wed | D8: Thu | E8: Fri | F8: Sat | G8: Sun | I8: Mon | J8: Tue | K8: Wed | L8: Thu | M8: Fri | N8: Sat | O8: Sun
E9: 1 | F9: 2 Course start | G9: 3 | I9: 1 L12 (U-II) | J9: 2 | K9: 3 L13 (U-II) | L9: 4 | M9: 5 L14 (U-II) | N9: 6 | O9: 7
A10: 4 L1 (U-I) | B10: 5 | C10: 6 L2 (U-I) | D10: 7 | E10: 8 L3 (U-I) | F10: 9 | G10: 10 | I10: 8 L15 (U-III) | J10: 9 Holiday | K10: 10 L16 (U-III) | L10: 11 | M10: 12 L17 (U-III) | N10: 13 | O10: 14
A11: 11 L4 (U-I) | B11: 12 | C11: 13 L5 (U-I) | D11: 14 Sankranti | E11: 15 Sankranti | F11: 16 | G11: 17 | I11: 15 L18 (U-III) | J11: 16 | K11: 17 L19 (U-III) | L11: 18 | M11: 19 L20 (U-III) | N11: 20 | O11: 21
A12: 18 L6 (U-I) | B12: 19 | C12: 20 L7 (U-I) | D12: 21 | E12: 22 L8 (U-II) | F12: 23 | G12: 24 | I12: 22 L21 (U-III) | J12: 23 | K12: 24 L22 (U-IV) | L12: 25 | M12: 26 L23 (U-IV) | N12: 27 | O12: 28
A13: 25 L9 (U-II) | B13: 26 Republic Day | C13: 27 L10 (U-II) | D13: 28 | E13: 29 L11 (U-II) | F13: 30 | G13: 31
A15: MARCH 2027
A16: Mon | B16: Tue | C16: Wed | D16: Thu | E16: Fri | F16: Sat | G16: Sun
A17: 1 L24 (U-IV) | B17: 2 Holiday | C17: 3 L25 (U-IV) | D17: 4 | E17: 5 L26 (U-IV) | F17: 6 | G17: 7
A18: 8 L27 (U-IV) | B18: 9 | C18: 10 L28 (U-IV) | D18: 11 | E18: 12 L29 (U-IV) | F18: 13 | G18: 14
A19: 15 L30 (U-V) | B19: 16 | C19: 17 L31 (U-V) | D19: 18 | E19: 19 L32 (U-V) | F19: 20 | G19: 21
A20: 22 L33 (U-V) | B20: 23 | C20: 24 L34 (U-V) | D20: 25 | E20: 26 L35 (U-V) | F20: 27 | G20: 28
A21: 29 | B21: 30 | C21: 31
A23: LEGEND
B24: Unit I lecture | F24: Unit II lecture | J24: Unit III lecture | N24: Unit IV lecture
B25: Unit V lecture | F25: Holiday | J25: Weekend / non-lecture | N25: Weekday, no lecture
A28: LECTURE DAYS SKIPPED
A29: Date | D29: Weekday | F29: Reason
A30: 46402 | D30: Friday | F30: Sankranti holiday (14-15 Jan)
A31: Other holidays given (14-Jan, 26-Jan, 09-Feb, 02-Mar) fall on non-lecture days; 07-Apr falls after the course end date. No other lecture is lost.
